Workbook

Sheet Остатки счетам баланса за 3 кв
C1: Вариант 25 | E1: Прокопьев Даниил | H1: 932204
B2: № счета | C2: Наименование | D2: Актив | E2: Пассив
B3: 1 | C3: Основные средства | D3: 3796966.7
B4: 2 | C4: Амортизация ОС | D4: 11363
B5: 50 | C5: Касса | D5: 11899.59
B6: 51 | C6: Расчетный счет | D6: 151321.74
B7: 55 | C7: Специальные счета в банках | D7: 27500
B8: 62 | C8: Покупатели и заказчики | D8: 1024000
B9: 71 | C9: Подотчетные лица | D9: 305.97
B10: 66 | C10: Краткосрочные кредиты и займы | E10: 19748.16
B11: 68 | C11: Налоги и сборы | E11: 114466.7
B12: 69 | C12: Соцстрахование | E12: 43480.97
B13: 80 | C13: Уставный капитал | E13: 4569350.3
B14: 82 | C14: Резервный капитал | E14: 132500
B15: 84 | C15: Нераспределенная прибыль | E15: 121084.86
C16: Итого | D16: 5000631 | E16: 5000631

Sheet Книга учета хоз. операций
B1: Вариант 25 | D1: Прокопьев Даниил | G1: 932204
F2: НДС на момент 14.04.2026 = 22%
F3: Однако мы берем НДС-20% т.к в задаче явно указаны даты до 26 года
B4: Книга учета хозяйственных операций ООО «ША»
B5: 1 Операция | C5: Оплата от покупателя, погашение кредита и процентов
B6: № | C6: Дата | D6: Наименование операции | E6: Дебет сч. | F6: Кредит сч. | G6: Сумма, руб.
B7: 1 | C7: 45931 | D7: Получена 100% оплата от покупателя за продукцию 3 кв. | E7: 51 | F7: 62 | G7: ='Остатки счетам баланса за 3 кв'!D8 -> 1024000
B8: 2 | C8: 45931 | D8: Начислены проценты по краткосрочному кредиту | E8: 91-2 | F8: 66-2 | G8: =1922 -> 1922 | H8: Проценты прямо из условия
B9: 3 | C9: 45931 | D9: Погашен краткосрочный кредит | E9: 66-1 | F9: 51 | G9: ='Остатки счетам баланса за 3 кв'!E10 -> 19748.16
B10: 4 | C10: 45931 | D10: Уплачены проценты по кредиту | E10: 66-2 | F10: 51 | G10: =G8 -> 1922 | H10: Та же сумма процентов
B11: 5 | C11: 45931 | D11: Начислен налог на имущество | E11: 99-3 | F11: 68-8 | G11: =(2.2%/4)*('Остатки счетам баланса за 3 кв'!D3-'Остатки счетам баланса за 3 кв'!D4) -> 20820.82
B12: 6 | C12: 45931 | D12: Уплачен налог на имущество | E12: 68-8 | F12: 51 | G12: =G11 -> 20820.82
B15: 2 Операция | C15: Командировка Таболкина
B16: № | C16: Дата | D16: Наименование операции | E16: Дебет сч. | F16: Кредит сч. | G16: Сумма, руб.
B17: 7 | C17: 45948 | D17: Получены наличные с расчётного счёта для выдачи аванса Таболкину Ф.И. | E17: 50 | F17: 51 | G17: =38250 -> 38250
B18: 8 | C18: 45948 | D18: Выданы деньги под отчет Таболкину Ф.И. | E18: 71 | F18: 50 | G18: =33700 -> 33700 | H18: Выданный аванс
B19: 9 | C19: 45952 | D19: Списаны командировочные расходы без НДС | E19: 44 | F19: 71 | G19: =G17-G21 -> 37748 | H19: Общий авансовый отчет 38250, из него НДС 502
B20: 10 | C20: 45952 | D20: Выделен НДС по командировочным расходам | E20: 19 | F20: 71 | G20: =502 -> 502 | H20: НДС выделяется отдельно
B21: 11 | C21: 45952 | D21: НДС по командировочным принят к вычету | E21: 68-2 | F21: 19 | G21: =G20 -> 502
B22: 12 | C22: 45953 | D22: Возмещен перерасход подотчетному лицу | E22: 71 | F22: 50 | G22: =G17-G18 -> 4550 | H22: Подотчетное лицо израсходовало по авансовому отчету всего 38250, а не 37748.
B25: 3 Операция | C25: Покупка оборудования и монтаж
B26: № | C26: Дата | D26: Наименование операции | E26: Дебет сч. | F26: Кредит сч. | G26: Сумма, руб.
B27: 13 | C27: 45980 | D27: Отражена стоимость оборудования, требующего монтажа, без НДС | E27: 07 | F27: 60 | G27: =G29/1.2 -> 188990 | H27: Из общей суммы покупки выделяем стоимость без НДС
B28: 14 | C28: 45980 | D28: Выделен входной НДС по оборудованию | E28: 19-1 | F28: 60 | G28: =G29-G27 -> 37798 | H28: Это не платеж, а выделение входного НДС
B29: 15 | C29: 45980 | D29: Оплачено оборудование поставщику | E29: 60 | F29: 51 | G29: 226788 | H29: Платим поставщику всю сумму по платежному поручению
B30: 16 | C30: 45980 | D30: Отражена стоимость монтажа оборудования | E30: 07 | F30: 60 | G30: =28000 -> 28000 | H30: В условии прямо сказано: монтаж 28000 без НДС
B31: 17 | C31: 45980 | D31: Оплачен монтаж оборудования | E31: 60 | F31: 51 | G31: =G30 -> 28000 | H31: Оплата подрядчику за монтаж
B32: 18 | C32: 45980 | D32: Сформированы капитальные вложения по оборудованию | E32: 08-4 | F32: 07 | G32: =G27+G30 -> 216990 | H32: Полная первоначальная стоимость без НДС: оборудование + монтаж
H33: Оборудование находится на регистрации в ЕГРОС поэтому мы не доводим его до ввода на 01 счет
B35: 4 Операция | C35: Обналичивание денег и выдача Фокину
B36: № | C36: Дата | D36: Наименование операции | E36: Дебет сч. | F36: Кредит сч. | G36: Сумма, руб.
B37: 19 | C37: 45965 | D37: Получены наличные из банка по денежному чеку | E37: 50 | F37: 51 | G37: 45000 | H37: Из-за самого факта “сняли наличные в банке и выдали их под отчет” налог платить не нужно.
B38: 20 | C38: 45965 | D38: Выданы деньги под отчет Фокину Я.Б. | E38: 71 | F38: 50 | G38: =G37 -> 45000 | H38: Это движение денег внутри компании: 51 → 50 → 71. Само по себе оно не образует ни НДС, ни НДФЛ
B41: 5 Операция | C41: Канцтовары, материалы и списание материалов в производство
B42: № | C42: Дата | D42: Наименование операции | E42: Дебет сч. | F42: Кредит сч. | G42: Сумма, руб.
B43: 21 | C43: 45978 | D43: Списаны канцтовары на общехозяйственные расходы | E43: 26 | F43: 71 | G43: =40725 -> 40725 | H43: Списаны канцтовары на общехозяйственные расходы
B44: 22 | C44: 45978 | D44: Оформлена чековая книжка / лимит под расчетный чек | E44: 55-2 | F44: 51 | G44: =205800 -> 205800 | H44: Оформлена чековая книжка / лимит под расчетный чек
B45: 23 | C45: 45978 | D45: Оплачены основные материалы расчетным чеком | E45: 60 | F45: 55-2 | G45: =G44 -> 205800 | H45: Оплачены основные материалы расчетным чеком
B46: 24 | C46: 45978 | D46: Оприходованы основные материалы без НДС | E46: 10 | F46: 60 | G46: =G45/1.2 -> 171500 | H46: Оприходованы основные материалы без НДС
B47: 25 | C47: 45978 | D47: Выделен НДС по основным материалам | E47: 19-3 | F47: 60 | G47: =G44-G46 -> 34300 | H47: Выделен НДС по основным материалам
...

Sheet ОСБ
B2: № пп | C2: №№ счет - кор. счет | D2: Сальдо начальное | F2: Обороты | H2: Сальдо исходящее
D3: Д | E3: К | F3: Д | G3: К | H3: Д | I3: К
B4: 1 | C4: 01* | D4: ='Остатки счетам баланса за 3 кв'!D3 -> 3796966.7 | H4: =SUM(D4) -> 3796966.7 | J4: оборудование еще на регистрации, поэтому 01/08 пока нет.
B5: 2 | C5: 02-20 | G5: ='Книга учета хоз. операций'!G50 -> 84156.25
B6: 3 | C6: 02-26 | G6: ='Книга учета хоз. операций'!G51 -> 13799.584
B7: 4 | C7: 02* | E7: ='Остатки счетам баланса за 3 кв'!D4 -> 11363 | G7: =SUM(G5:G6) -> 97955.834 | I7: =E7+G7 -> 109318.83
B8: 5 | C8: 07-60 | F8: ='Книга учета хоз. операций'!G27 -> 188990
B9: 6 | C9: 07-60 | F9: ='Книга учета хоз. операций'!G30 -> 28000
B10: 7 | C10: 07-08-4 | G10: ='Книга учета хоз. операций'!G32 -> 216990
B11: 8 | C11: 07* | F11: =SUM(F8:F9) -> 216990 | G11: =SUM(G10) -> 216990
B12: 9 | C12: 08-04-07 | F12: =G10 -> 216990
B13: 10 | C13: 08* | F13: =SUM(F12) -> 216990 | H13: =SUM(F13) -> 216990
B14: 11 | C14: 10-60 | F14: ='Книга учета хоз. операций'!G46 -> 171500
B15: 12 | C15: 10-20 | G15: ='Книга учета хоз. операций'!G48 -> 170547
B16: 13 | C16: 10* | F16: =SUM(F14) -> 171500 | G16: =SUM(G15) -> 170547 | H16: =F16-G16 -> 953
B17: 14 | C17: 19-71 | F17: ='Книга учета хоз. операций'!G20 -> 502
B18: 15 | C18: 19-1-60 | F18: ='Книга учета хоз. операций'!G28 -> 37798
B19: 16 | C19: 19-3-60 | F19: ='Книга учета хоз. операций'!G47 -> 34300
B20: 17 | C20: 19-3-60 | F20: ='Книга учета хоз. операций'!G59 -> 8666.6667
B21: 18 | C21: 19-68-2 | G21: ='Книга учета хоз. операций'!G21 -> 502
B22: 19 | C22: 19-2-68-2 | G22: ='Книга учета хоз. операций'!G49 -> 34109.4
B23: 20 | C23: 19-3-68-2 | G23: ='Книга учета хоз. операций'!G59 -> 8666.6667
B24: 21 | C24: 19* | F24: =SUM(F17:F20) -> 81266.667 | G24: =SUM(G21:G23) -> 43278.067 | H24: =F24-G24 -> 37988.6 | J24: По оборудованию НДС пока останется на 19, если мы не принимаем его к вычету до регистрации.
B25: 22 | C25: 20-10 | F25: ='Книга учета хоз. операций'!G48 -> 170547
B26: 23 | C26: 20-70 | F26: ='Книга учета хоз. операций'!G64 -> 291000
B27: 24 | C27: 20-69 | F27: ='Книга учета хоз. операций'!G66 -> 87882
B28: 25 | C28: 20-02 | F28: ='Книга учета хоз. операций'!G50 -> 84156.25
B29: 26 | C29: 20-43 | G29: ='Книга учета хоз. операций'!G76 -> 506868.2
B30: 27 | C30: 20* | F30: =SUM(F25:F28) -> 633585.25 | G30: =SUM(G29) -> 506868.2 | H30: =F30-G30 -> 126717.05
B31: 28 | C31: 26-71 | F31: ='Книга учета хоз. операций'!G43 -> 40725
B32: 29 | C32: 26-70 | F32: ='Книга учета хоз. операций'!G65 -> 269820
B33: 30 | C33: 26-69 | F33: ='Книга учета хоз. операций'!G67 -> 81485.64
B34: 31 | C34: 26-02 | F34: ='Книга учета хоз. операций'!G51 -> 13799.584
B35: 32 | C35: 26-90-2 | G35: ='Книга учета хоз. операций'!G82 -> 405830.22
B36: 33 | C36: 26* | F36: =SUM(F31:F34) -> 405830.22 | G36: =SUM(G35) -> 405830.22 | H36: =F36-G36 -> 0
B37: 34 | C37: 43-20 | F37: ='Книга учета хоз. операций'!G76 -> 506868.2
B38: 35 | C38: 43* | F38: =SUM(F37) -> 506868.2 | H38: =SUM(F38) -> 506868.2
B39: 36 | C39: 44-71 | F39: ='Книга учета хоз. операций'!G19 -> 37748
B40: 37 | C40: 44-60 | F40: ='Книга учета хоз. операций'!G56 -> 43333.333
B41: 38 | C41: 44-90-2 | G41: ='Книга учета хоз. операций'!G81 -> 81081.333
...

Sheet Форма 1
C2: Актив | D2: Код показателя | E2: На начало отчетного года | F2: На конец отчетного периода
C3: 1 | D3: 2 | E3: 3 | F3: 4
C4: I. ВНЕОБОРОТНЫЕ АКТИВЫ Основные средства (01, 02) | D4: 120 | E4: =ОСБ!D4-ОСБ!E7 -> 3785603.7 | F4: =ОСБ!H4-ОСБ!I7 -> 3687647.9
C5: Незавершенное строительство (07, 08, 016) | D5: 130 | E5: =ОСБ!D11+ОСБ!D13 -> 0 | F5: =ОСБ!H11+ОСБ!H13 -> 216990
C6: Итого по разделу I | D6: 190 | E6: =SUM(E4:E5) -> 3785603.7 | F6: =SUM(F4:F5) -> 3904637.9
C7: II. ОБОРОТНЫЕ АКТИВЫ в том числе: сырье, материалы и другие аналогичные ценности (10, 14, 16) | D7: 211 | E7: =ОСБ!D16 -> 0 | F7: =ОСБ!H16 -> 953
C8: затраты в незавершенном производстве (20, 21, 23, 29, 44, 46) | D8: 213 | E8: =ОСБ!D30 -> 0 | F8: =ОСБ!H30 -> 126717.05
C9: готовая продукция и товары для перепродажи (16, 41, 43) | D9: 214 | E9: =ОСБ!D38 -> 0 | F9: =ОСБ!H38 -> 506868.2
C10: Налог на добавленную стоимость по приобретенным ценностям (19) | D10: 220 | E10: =ОСБ!D24 -> 0 | F10: =ОСБ!H24 -> 37988.6
C11: в том числе: покупатели и заказчики (62, 63, 76) | D11: 241 | E11: =ОСБ!D79 -> 1024000 | F11: =ОСБ!H79 -> 0
C12: прочие дебиторы (68, 69) | D12: 246 | E12: =ОСБ!D107 -> 305.97 | F12: =ОСБ!H107+ОСБ!H77 -> 4580.97
C13: в том числе: касса (50) | D13: 261 | E13: =ОСБ!D48 -> 11899.59 | F13: =ОСБ!H48 -> 11899.59
C14: расчетные счета (51) | D14: 262 | E14: =ОСБ!D62 -> 151321.74 | F14: =ОСБ!H62 -> 0
C15: прочие денежные средства (55, 57) | D15: 264 | E15: =ОСБ!D65 -> 27500 | F15: =ОСБ!H65 -> 27500
C16: Итого по разделу II | D16: 290 | E16: =SUM(E7:E15) -> 1215027.3 | F16: =SUM(F7:F15) -> 716507.41
C17: БАЛАНС (сумма строк 190+290) | D17: 300 | E17: =E16+E6 -> 5000631 | F17: =F16+F6 -> 4621145.3
C19: Пассив
C20: III. КАПИТАЛ И РЕЗЕРВЫ Уставный капитал (80) | D20: 410 | E20: =ОСБ!E108 -> 4569350.3 | F20: =ОСБ!I108 -> 4569350.3
C21: Резервный капитал (82) | D21: 430 | E21: =ОСБ!E109 -> 132500 | F21: =ОСБ!I109 -> 132500
C22: Нераспределенная прибыль прошлых лет (84-2) | D22: 460 | E22: =ОСБ!E111 -> 121084.86 | F22: =0 -> 0
C23: Непокрытый убыток отчетного года (84-1) | D23: 475 | E23: х | F23: =ОСБ!H111 -> 388569.52
C24: Итого по разделу III | D24: 490 | E24: =SUM(E20:E22) -> 4822935.2 | F24: =F20+F21-F23 -> 4313280.8
C25: V. КРАТКОСРОЧНЫЕ ОБЯЗАТЕЛЬСТВА Займы и кредиты (66) | D25: 610 | E25: =ОСБ!E83 -> 19748.16 | F25: =ОСБ!I83 -> 0 | G25: У нас краткосрочный кредит
C26: в том числе: поставщики и подрядчики (60, 76) | D26: 621 | E26: =ОСБ!E77 -> 0 | F26: =ОСБ!I77 -> 0
C27: задолженность перед персоналом организации (70) | D27: 624 | E27: =ОСБ!E100 -> 0 | F27: =ОСБ!I100 -> 0
C28: задолженность перед государственными внебюджетными фондами (69) | D28: 625 | E28: =ОСБ!E95 -> 43480.97 | F28: =ОСБ!I95 -> 43480.97
C29: задолженность по налогам и сборам (68) | D29: 626 | E29: =ОСБ!E91 -> 114466.7 | F29: =ОСБ!I91 -> 71188.633
C30: Прочие краткосрочные обязательства | D30: 660 | E30: =0 -> 0 | F30: =ОСБ!I62 -> 193194.88 | G30: Мне не хватало денег что бы закрыть все расчеты, особенно после вычетов НДФЛ и налога на имущество
C31: Итого по разделу V | D31: 690 | E31: =SUM(E25:E29) -> 177695.83 | F31: =SUM(F25:F30) -> 307864.48
C32: БАЛАНС (сумма строк 490+590+690) | D32: 700 | E32: =E31+E24 -> 5000631 | F32: =F31+F24 -> 4621145.3
E34: =E17-E32 -> 0 | F34: =F32-F17 -> 0

Sheet Форма 2
B2: Отчет о прибылях и убытках, форма №2
B3: Показатель | C3: Код показателя | D3: За отчетный период
B4: Доходы и расходы по обычным видам деятельности
B5: Выручка (нетто) от продажи товаров, продукции, работ, услуг (за минусом налога на добавленную стоимость, акцизов и аналогичных обязательных платежей) | C5: 10 | D5: 0 | E5: В 4 квартале продукция не отгружалась (нет оборота по Кт 90-1). Счёт 90-1 в ОСБ отсутствует.
B6: Себестоимость проданных товаров, продукции, работ, услуг | C6: 20 | D6: 0 | E6: Нет продаж → нет списания себестоимости (Дт 90-2 с Кт 43 отсутствует).
B7: Валовый убыток | C7: 29 | D7: =D5-D6 -> 0
B8: Коммерческие расходы (44) | C8: 30 | D8: =ОСБ!F112 -> 81081.333 | E8: Оборот по дебету счёта 90-2 в части коммерческих расходов (строка 109 ОСБ). Это сумма, списанная со счёта 44.
B9: Управленческие расходы | C9: 40 | D9: =ОСБ!F113 -> 405830.22 | E9: Оборот по дебету счёта 90-2 в части общехозяйственных расходов (строка 110 ОСБ). Это сумма, списанная со счёта 26.
B10: Убыток от продаж (010-020-030-040) | C10: 50 | D10: =-(D7-D9-D8) -> 486911.56 | E10: Разница между валовой прибылью и расходами на продажу и управление. В ОСБ этот же результат отражён как оборот Дт 99 Кт 90-9 (строка 111 ОСБ, сумма G114).
B11: Операционные доходы и расходы
B12: Проценты к уплате | C12: 70 | D12: =ОСБ!F116 -> 1922 | E12: Оборот по дебету счёта 91-2 (строка 113 ОСБ). Это проценты по кредиту.
B13: Прочие операционные доходы | C13: 90 | D13: =0 -> 0 | E13: Оборотов по Кт 91-1 нет.
B14: Прочие операционные расходы | C14: 100 | D14: 0 | E14: Кроме процентов других расходов по сч. 91-2 нет.
B15: 3. Внереализационные доходы и расходы
B16: Прибыль до налогообложения (строки 050 + 060 – 070 + 080 + 090 – 100 + 120 – 130) | C16: 140 | D16: =D10+D12 -> 488833.56 | E16: Сумма убытка от продаж и процентов к уплате. В ОСБ это сумма дебетовых оборотов по сч. 99 в корреспонденции с 90-9 и 91-9
B17: Налог на прибыль и иные аналогичные обязательные платежи (налог на имущество) | C17: 150 | D17: =ОСБ!F122 -> 20820.82
B18: Убыток от обычной деятельности | C18: 160 | D18: =D16+D17 -> 509654.38
B19: Чистаый убыток отчетного периода (160+170-180) | C19: 190 | D19: =D18 -> 509654.38 | E19: Соответствует сумме, списанной на счёт 84
E21: Мы в убытке
D22: =D19-'Книга учета хоз. операций'!G85 -> 0

Sheet Финансовое состояние
C2: на начало отченого периода | D2: на конец отченого периода | E2: Выводы
C3: Платежеспособность, %
B4: DAR | C4: ='Форма 1'!E31/'Форма 1'!E17 -> 0.035534682 | D4: ='Форма 1'!F31/'Форма 1'!F17 -> 0.066620819 | E4: Очень низкая доля обязательств в активах. Предприятие практически не зависит от заёмных средств. Финансовая устойчивость высокая.
B5: DER | C5: ='Форма 1'!E31/'Форма 1'!E24 -> 0.036843918 | D5: ='Форма 1'!F31/'Форма 1'!F24 -> 0.071375943 | E5: На 1 рубль собственного капитала приходится 7 копеек заёмного. Минимальный финансовый риск.
B6: TIE | C6: =IF('Форма 2'!D12=0,"Нет исходных данных",-'Форма 2'!D10/'Форма 2'!D12) -> -253.33588 | E6: Отрицательное значение из-за убытка. Операционная деятельность не покрывает проценты. Необходимо восстановление прибыльности.
B7: Ликвидность
B8: CR | C8: ='Форма 1'!E16/'Форма 1'!E31 -> 6.8376804 | D8: ='Форма 1'!F16/'Форма 1'!F31 -> 2.3273468 | E8: Текущая ликвидность выше нормы (1,5–2). Оборотных активов достаточно для погашения краткосрочных обязательств.
B9: QR | C9: =('Форма 1'!E12+'Форма 1'!E13+'Форма 1'!E14+'Форма 1'!E15)/'Форма 1'!E32 -> 0.038200639 | D9: =('Форма 1'!F12+'Форма 1'!F13+'Форма 1'!F14+'Форма 1'!F15)/'Форма 1'!F32 -> 0.0095172425 | E9: Критически низкая быстрая ликвидность. Практически отсутствуют ликвидные активы (деньги + дебиторка) для срочного погашения долгов.
B10: AR | C10: =('Форма 1'!E13+'Форма 1'!E14+'Форма 1'!E15)/'Форма 1'!E31 -> 1.0733022 | D10: =('Форма 1'!F13+'Форма 1'!F14+'Форма 1'!F15)/'Форма 1'!F31 -> 0.12797706 | E10: Абсолютная ликвидность ниже нормы (≥0,2). Денежных средств недостаточно для немедленной оплаты обязательств.
B11: NWC, тыс. руб. | C11: ='Форма 1'!E16-'Форма 1'!E31 -> 1037331.5 | D11: ='Форма 1'!F16-'Форма 1'!F31 -> 408642.93 | E11: Чистый оборотный капитал положительный. Предприятие имеет собственные оборотные средства, краткосрочная платёжеспособность обеспечена.
B12: Рентабельность, %
B13: ROA | C13: =-'Форма 2'!D19/'Форма 1'!E17 -> -0.10191801 | D13: =-'Форма 2'!D19/'Форма 1'!F17 -> -0.11028746 | E13: Убыточность активов. Каждый рубль активов приносит 11 копеек убытка. Эффективность использования имущества низкая.
B14: ROE | C14: =-'Форма 2'!D19/'Форма 1'!E24 -> -0.10567307 | D14: =-'Форма 2'!D19/'Форма 1'!F24 -> -0.11815933 | E14: Убыточность собственного капитала. Собственники не получают отдачи на вложенные средства.
B15: ROIC | C15: =-('Форма 2'!D19+'Форма 2'!D12*(1-0.2))/('Форма 1'!E24+'Форма 1'!E29) -> -0.10353461 | D15: =-('Форма 2'!D19+'Форма 2'!D12*(1-0.2))/('Форма 1'!F24+'Форма 1'!F29) -> -0.11659153 | E15: Инвестированный капитал используется неэффективно, совокупная отдача отрицательная.
B16: GPM | C16: н.д | E16: Валовая рентабельность не рассчитывается из-за отсутствия выручки.
B17: Деловая активность
B18: RT | C18: =1 -> 1 | E18: Оборачиваемость дебиторской задолженности условно равна 1 (дебиторка отсутствует или минимальна). Покупатели платят сразу.
B19: CP, день | C19: 0 | E19: Период инкассации дебиторской задолженности нулевой, что подтверждает отсутствие коммерческого кредитования.
B20: Риск банкротства Zo | C20: =1.2*C21+1.4*C22+3.3*C23+0.6*C24+0.999*C25 -> 4.1628169 | E20: Значение >2,9 указывает на низкую вероятность банкротства. Несмотря на убытки, структура баланса (высокий собственный капитал, низкие долги) обеспечивает финансовую устойчивость.
B21: x1 | C21: ='Форма 1'!E16/'Форма 1'!E17 -> 0.2429748
B22: x2 | C22: =-('Форма 1'!F22-'Форма 1'!F23)/'Форма 1'!F17 -> 0.084085112
B23: x3 | C23: =-'Форма 2'!D16/'Форма 1'!F17 -> -0.10578191
B24: x4 | C24: ='Форма 1'!E16/'Форма 1'!E31 -> 6.8376804
B25: x5 | C25: ='Форма 2'!D5/'Форма 1'!F17 -> 0
